Workbook

Sheet Cotizacion
D1: Calle Aquiles Serdán S/N
D2: C. P. 42820, Michimaloya Centro, Tula de Allende Hgo.
D3: Oficina +52 (773) 7240055
D4: www.immee.com.mx
D5: immee_013@hotmail.com
B8: Apoyando el consumo inteligente de energía eléctrica
A10: Ing. Lemuel Cruz Nieto | C10: Tula de Allende Hgo, a 11 de febrero de 2025
A11: Supervisor de proyectos
A12: TRACSA ENERGIA
A14: Presente | E14: COT. IMM-042-2025
A16: Atendiendo a su amable solicitud, le presentamos a su consideración el presupuesto por el servicio de "SUMINISTRO E INSTALACIÓN DE CIRCUITOS DE FUERZA PARA GENERADOR DE 2500 kW en parque Industrial AMEXHE Apaseo el Alto Guanajuato" en base al siguiente alcance.
A18: No. | B18: CONCEPTO | C18: UNIDIDAD | D18: CANTIDAD | E18: P.U | F18: IMPORTE
A19: 1 | B19: CHAROLA & SOPORTERIA - CHAROLA TIPO NEMA 8C
A20: 1.1 | B20: Suministro e instalación de charola tipo escalera perfil Z para servicio pesado de 30". Marca Croos line | C20: PZA | D20: 6 | E20: ='M0 (1)'!H97/6 -> 7744.8082 | F20: =D20*E20 -> 46468.849
A21: 1.2 | B21: Suministro e instalación de tapa para charola tipo escalera de 30". | C21: JGO | D21: 6 | E21: ='M0 (2)'!H97/6 -> 2203.3584 | F21: =D21*E21 -> 13220.15
A22: 1.3 | B22: Suministro e instalación de curva vertical exterior de 90° para charola tipo escalera de 30", en servicio pesado radio 12. | C22: PZA | D22: 4 | E22: ='M0 (3)'!H98 -> 2328.0623 | F22: =D22*E22 -> 9312.2492
A23: 1.4 | B23: Suministro e instalación de tapa para curva vertical exterior de 90° para charola tipo escalera para servicio pesado de 30", radio 12 | C23: PZA | D23: 4 | E23: ='M0 (4)'!H98 -> 1748.9644 | F23: =D23*E23 -> 6995.8575
A24: 1.5 | B24: Suministro e instalación de curva horizontal de 90° para charola tipo escalera para servicio pesado de 30", radio 12. Marca soportes eléctricos. | C24: PZA | D24: 2 | E24: =E22 -> 2328.0623 | F24: =D24*E24 -> 4656.1246
A25: 1.6 | B25: Suministro e instalación de tapa para curva horizontal de 90° para charola tipo escalera de 30", radio 12. Marca soportes eléctricos. | C25: PZA | D25: 2 | E25: =E23 -> 1748.9644 | F25: =D25*E25 -> 3497.9288
A26: 1.7 | B26: Suministro e instalación de soporte elaborado en sitio a base de unicanal solido galvanizado de 4x4, tornilleria galvanizada para su correcta instalación, varilla roscada galvanizada de 3 metros de largo X 1/2", mordaza sujeta barra. | C26: PZA | D26: 6 | E26: ='M0 (5)'!H98 -> 3810.5221 | F26: =D26*E26 -> 22863.133
A27: 1.8 | B27: Suministro e instalación de conector de charola para servicio pesado de 30" a caja. | C27: PZA | D27: 2 | E27: ='M0 (6)'!H98 -> 2358.6105 | F27: =D27*E27 -> 4717.2209
A28: 2 | B28: TORNILLERIA & ZAPATAS
A29: 2.1 | B29: Suministro e instalación de zapata ponchable para cable de cobre cañon largo calibre 500 KCM, con 2 ojillos de 1/2". | C29: PZA | D29: 80 | E29: ='M0 (7)'!H98 -> 1611.3597 | F29: =D29*E29 -> 128908.77
A30: 2.2 | B30: Suministro e instalación de manga termocontractil para nivel de aislamiento de 600 V, en calibre 500 KCM. | C30: PZA | D30: 4 | E30: ='M0 (8)'!H98 -> 3568.2161 | F30: =D30*E30 -> 14272.865
A31: 2.3 | B31: Suministro e instalación de tornillo tropicalizado de 1/2" con 2" de largo, incluye tuerca, roldana plana y de presion | C31: PZA | D31: 40 | E31: =12*1.8 -> 21.6 | F31: =D31*E31 -> 864
A32: 2.4 | B32: Suministro e instalación de tornillo tropicalizado de 1/2" con 4" de largo, incluye tuerca, roldana plana y de presion | C32: PZA | D32: 40 | E32: =16*1.8 -> 28.8 | F32: =D32*E32 -> 1152
A33: 3 | B33: CORTAFUEGO
A34: 3.1 | B34: Suministro e instalación de sistema corta fuego con lana mineral y compuesto SF-ONE. | C34: PZA | D34: 2 | E34: ='M0 (9)'!H98 -> 29218.802 | F34: =D34*E34 -> 58437.604
A35: 4 | B35: ACCESORIOS
A36: 4.1 | B36: Suministro e instalación de materiales consumibles.- Cintillos para exterior- Cintas de aislar para identificación de terminales- Discos de corte | C36: LOTE | D36: 1 | E36: 5480 | F36: =D36*E36 -> 5480
A37: 4.2 | B37: Suministro de materiales e instalacion de cuellos de lona flexibles en gargantas primarias de generador electrico | C37: PZA | D37: 1 | E37: 5860 | F37: =D37*E37 -> 5860
A38: 4.3 | B38: Suministro e instalación de cable de cobre THW calibre 12 AWG en color verde con zapatas ponchables en charolas de generador | C38: SERV | D38: 1 | E38: 2600 | F38: =D38*E38 -> 2600
A39: 4.4 | B39: Suministro e instalación de tapones para unicanal de 4x4 y varilla roscada | C39: SERV | D39: 1 | E39: 1600 | F39: =D39*E39 -> 1600
A40: 4.5 | B40: Suministro e instalación de tapones para esparrago | C40: SERV | D40: 1 | E40: 1240 | F40: =D40*E40 -> 1240
A41: 5 | B41: SERVICIOS & MANO DE OBRA
A42: 5.1 | B42: Servicio de prueba de resistencia de aislamiento a cable de baja tensión tipo THW LS calibre 500 KCM . El concepto incluye: - Desconexión en caso de ser necesario - Conexión de terminales - Repriete en conexiónes con torque requerido - Prueba de resistencia de aislamiento con inyección de corriente directa con equipo calibrado ante la EMA | C42: PBA | D42: 38 | E42: 650 | F42: =D42*E42 -> 24700
A43: 5.2 | B43: Servicio de mano de obra por los siguientes conceptos. - Instalación de materiales de partida anterior - Instalación de cable de cobre 500 mts THW LS calibre 500 MCM. (En charola de 30 " 12 puntas por fase (3 fases +2 cables de tierra). De acuerdo a medidas del cliente. | C43: SERV | D43: 1 | E43: ='M0 (10)'!H97 -> 42106.909 | F43: =D43*E43 -> 42106.909
A44: 6 | B44: PLATAFORMA ARTICULADA
A45: 6.1 | B45: Renta de plataforma articulada para trabajos en altura | C45: SERV | D45: 1 | E45: ='MAT (11)'!H124 -> 24196.249 | F45: =D45*E45 -> 24196.249
A46: 7 | B46: SEGURIDAD
...

Sheet Hoja1

Sheet Semana completa MAT
A1: I M M E E S. A. D E C. V.
A2: A N A L I S I S D E P R E C I O U N I T A R I O
A3: COTIZACION:
A4: FECHA:
A5: PARTIDA 1
A6: REV-06-feb-2021
A7: MATERIALES.
A8: DESCRIPCION | E8: UNIDAD | F8: CANT. | G8: P.U. | H8: IMPORTE | J8: MATERIALES
A9: charola tipo escalera perfil Z para servicio pesado de 30" | E9: Pza | F9: 6 | G9: 2540.01 | H9: =G9*F9 -> 15240.06
A10: tapa para charola tipo escalera de 30". | E10: Pza | F10: 6 | G10: 1001 | H10: =G10*F10 -> 6006
A11: curva vertical exterior de 90° para charola tipo escalera de 30 | E11: Pza | F11: 4 | G11: 450.5 | H11: =G11*F11 -> 1802
A12: tapa para curva vertical exterior de 90° para charola tipo escalera para servicio pesado de 30" | E12: Pza | F12: 4 | G12: 136.52 | H12: =G12*F12 -> 546.08
A13: curva horizontal de 90° para charola tipo escalera para servicio pesado de 30" | E13: Pza | F13: 2 | G13: 620.97 | H13: =G13*F13 -> 1241.94
A14: base de unicanal solido galvanizado de 4x4 | E14: Pza | F14: 6 | G14: 382.32 | H14: =G14*F14 -> 2293.92
A15: tornilleria galvanizada | E15: Pza | F15: 6 | G15: 200 | H15: =G15*F15 -> 1200
A16: varilla roscada galvanizada de 3 metros de largo X 1/2" | E16: Pza | F16: 6 | G16: 70 | H16: =G16*F16 -> 420
A17: conector de charola para servicio pesado de 30 | E17: Pza | F17: 2 | G17: 467.05 | H17: =G17*F17 -> 934.1
A18: zapata ponchable para cable de cobre cañon largo calibre 500 KCM, con 2 ojillos de 1/2 | E18: Pza | F18: 80 | G18: 495.41 | H18: =G18*F18 -> 39632.8
A19: manga termocontractil para nivel de aislamiento de 600 V, en calibre 500 KCM. | E19: Pza | F19: 4 | G19: 212.43 | H19: =G19*F19 -> 849.72
A20: tornillo tropicalizado de 1/2" con 2" de largo | E20: Pza | F20: 40 | G20: 15 | H20: =G20*F20 -> 600
... A24: cuellos de lona flexibles en gargantas primarias de generador electrico | E24: Pza | F24: 1 | G24: 160.08 | H24: =G24*F24 -> 160.08
A25: cable de cobre THW calibre 12 AWG | E25: mt | F25: 1 | G25: 12.63 | H25: =G25*F25 -> 12.63 | L25: NOTA: CONSIDERAR LA JORNADA DE 8.0 HORAS, AUNQUE EN IMMEE SE TRABAJE JORNADA LARGA CONVENIDA, Y DOMINGO DESCANSO
A26: tapones para unicanal de 4x4 y varilla roscada | E26: Pza | F26: 1 | G26: 27.6 | H26: =G26*F26 -> 27.6
A27: tapones para esparrago | E27: Pza | F27: 1 | G27: 70.34 | H27: =G27*F27 -> 70.34
A28: cable de cobre 500 mts THW LS calibre 500 MCM | E28: CARRETE | F28: 1 | G28: 897.84 | H28: =G28*F28 -> 897.84
A29: Renta de una plataforma de elevacion | E29: Pza | F29: 1 | G29: 48000 | H29: =G29*F29 -> 48000 | I29: =H29*1.455 -> 69840
G30: SUBT 1 | H30: =SUM(H9:H29) -> 122431.61
A32: MANO DE OBRA SIN INDIRECTOS | O32: HORARIOS DE TRABAJO | V32: HORAS RESULTANTES | Y32: PERSONAL PEOPUESTO
A33: PERSONAL. | E33: UNIDAD | F33: CANT. | G33: HORA NORMAL | H33: IMPORTE | I33: CANT. | J33: Hr. Extra | K33: IMPORTE | L33: CANT. | M33: Dom, ó Fest.TRIPLE | N33: IMPORTE | O33: L | P33: M | Q33: MI | R33: J | S33: V | T33: S | U33: D | V33: N | W33: D | X33: T
A34: SUPERVISOR DE SEGURIDAD CERTIFICADO | E34: hr | G34: 390.39 | H34: =F34*G34 -> 0 | J34: 358.81 | K34: =I34*J34 -> 0 | M34: 538.27 | N34: =L34*M34 -> 0 | V34: =+O34+P34+Q34+R34+S34+T34+U34-W34-X34 -> 0
A35: SUPERVISOR DE SEGURIDAD | E35: hr | G35: 243.45 | H35: =F35*G35 -> 0 | J35: 211.59 | K35: =I35*J35 -> 0 | M35: 317.39 | N35: =L35*M35 -> 0 | V35: =+O35+P35+Q35+R35+S35+T35+U35-W35-X35 -> 0 | Y35: OSWALDO Z-GABRIEL
A36: SUPERVISOR ELECTRICO | E36: hr | G36: 390.39 | H36: =F36*G36 -> 0 | J36: 358.81 | K36: =I36*J36 -> 0 | M36: 538.22 | N36: =L36*M36 -> 0 | V36: =+O36+P36+Q36+R36+S36+T36+U36-W36-X36 -> 0 | Y36: ADRIAN
A37: TECNICO DE PRUEBAS ELECTRICAS | E37: hr | G37: 231.67 | H37: =F37*G37 -> 0 | J37: 197.63 | K37: =I37*J37 -> 0 | M37: 296.45 | N37: =L37*M37 -> 0 | V37: =+O37+P37+Q37+R37+S37+T37+U37-W37-X37 -> 0 | Y37: HECTOR
A38: CABO OBRA ELECTRICA | E38: hr | G38: 310.62 | H38: =F38*G38 -> 0 | J38: 291.24 | K38: =I38*J38 -> 0 | M38: 436.87 | N38: =L38*M38 -> 0 | V38: =+O38+P38+Q38+R38+S38+T38+U38-W38-X38 -> 0
A39: LINIERO | E39: hr | G39: 310.62 | H39: =F39*G39 -> 0 | J39: 291.24 | K39: =I39*J39 -> 0 | M39: 436.87 | N39: =L39*M39 -> 0 | V39: =+O39+P39+Q39+R39+S39+T39+U39-W39-X39 -> 0 | Y39: JOSE J
A40: ESPECIALISTA DE MANTTO ELECTRICO | E40: hr | H40: =F40*G40 -> 0 | J40: 0 | K40: =I40*J40 -> 0 | M40: 0 | N40: =L40*M40 -> 0 | V40: =+O40+P40+Q40+R40+S40+T40+U40-W40-X40 -> 0
A41: TECNICO EN INSTRUMENTACION | E41: hr | G41: 199.6 | H41: =F41*G41 -> 0 | J41: 159.6 | K41: =I41*J41 -> 0 | M41: 239.4 | N41: =L41*M41 -> 0 | V41: =+O41+P41+Q41+R41+S41+T41+U41-W41-X41 -> 0
A42: OFICIAL ELECTRICO/ELECTROMECANICO | E42: hr | G42: 199.6 | H42: =F42*G42 -> 0 | J42: 159.6 | K42: =I42*J42 -> 0 | M42: 239.4 | N42: =L42*M42 -> 0 | V42: =+O42+P42+Q42+R42+S42+T42+U42-W42-X42 -> 0
A43: ASISTENTE DE DISEÑO | E43: hr | G43: 199.6 | H43: =F43*G43 -> 0 | J43: 159.6 | K43: =I43*J43 -> 0 | M43: 239.4 | N43: =L43*M43 -> 0 | V43: =+O43+P43+Q43+R43+S43+T43+U43-W43-X43 -> 0
A44: ELECTRICISTA -B | E44: hr | G44: 211.15 | H44: =F44*G44 -> 0 | J44: 173.29 | K44: =I44*J44 -> 0 | M44: 259.94 | N44: =L44*M44 -> 0 | V44: =+O44+P44+Q44+R44+S44+T44+U44-W44-X44 -> 0 | Y44: GERMAN
...

Sheet Semana completa M0
A1: I M M E E S. A. D E C. V.
A2: A N A L I S I S D E P R E C I O U N I T A R I O
A3: COTIZACION:
A4: FECHA:
A5: PARTIDA 1
A6: REV-06-feb-2021
A7: MATERIALES.
A8: DESCRIPCION | E8: UNIDAD | F8: CANT. | G8: P.U. | H8: IMPORTE | J8: MANO DE OBRA
A9: Consumible | E9: Pza | H9: =G9*F9 -> 0
E10: Pza | H10: =G10*F10 -> 0
E11: Pza | H11: =G11*F11 -> 0
E12: Pza | H12: =G12*F12 -> 0
E13: Pza | H13: =G13*F13 -> 0
E14: Pza | H14: =G14*F14 -> 0
E15: Pza | H15: =G15*F15 -> 0
E16: Pza | H16: =G16*F16 -> 0 | I16: =H16*1.455 -> 0
G17: SUBT 1 | H17: =SUM(H9:H16) -> 0
A19: MANO DE OBRA SIN INDIRECTOS | O19: HORARIOS DE TRABAJO | V19: HORAS RESULTANTES | Y19: PERSONAL PEOPUESTO
A20: PERSONAL. | E20: UNIDAD | F20: CANT. | G20: HORA NORMAL | H20: IMPORTE | I20: CANT. | J20: Hr. Extra | K20: IMPORTE | L20: CANT. | M20: Dom, ó Fest.TRIPLE | N20: IMPORTE | O20: L | P20: M | Q20: MI | R20: J | S20: V | T20: S | U20: D | V20: N | W20: D | X20: T
A21: SUPERVISOR DE SEGURIDAD CERTIFICADO | E21: hr | G21: 390.39 | H21: =F21*G21 -> 0 | J21: 358.81 | K21: =I21*J21 -> 0 | M21: 538.27 | N21: =L21*M21 -> 0 | V21: =+O21+P21+Q21+R21+S21+T21+U21-W21-X21 -> 0
A22: SUPERVISOR DE SEGURIDAD | E22: hr | G22: 317.98 | H22: =F22*G22 -> 0 | J22: 326.25 | K22: =I22*J22 -> 0 | M22: 489.37 | N22: =L22*M22 -> 0 | V22: =+O22+P22+Q22+R22+S22+T22+U22-W22-X22 -> 0 | Y22: OSWALDO Z-GABRIEL
A23: SUPERVISOR ELECTRICO | E23: hr | F23: =9.5*5 -> 47.5 | G23: 390.39 | H23: =F23*G23 -> 18543.525 | I23: 6 | J23: 358.81 | K23: =I23*J23 -> 2152.86 | M23: 538.22 | N23: =L23*M23 -> 0 | V23: =+O23+P23+Q23+R23+S23+T23+U23-W23-X23 -> 0 | Y23: ADRIAN
A24: TECNICO DE PRUEBAS ELECTRICAS | E24: hr | G24: 317.98 | H24: =F24*G24 -> 0 | J24: 244.27 | K24: =I24*J24 -> 0 | M24: 489.37 | N24: =L24*M24 -> 0 | V24: =+O24+P24+Q24+R24+S24+T24+U24-W24-X24 -> 0 | Y24: HECTOR
A25: CABO OBRA ELECTRICA | E25: hr | G25: 310.62 | H25: =F25*G25 -> 0 | J25: 335 | K25: =I25*J25 -> 0 | M25: 436.87 | N25: =L25*M25 -> 0 | V25: =+O25+P25+Q25+R25+S25+T25+U25-W25-X25 -> 0
A26: LINIERO | E26: hr | F26: =9.5*5 -> 47.5 | G26: 209.25 | H26: =F26*G26 -> 9939.375 | I26: 6 | J26: 221.7 | K26: =I26*J26 -> 1330.2 | M26: 437.63 | N26: =L26*M26 -> 0 | V26: =+O26+P26+Q26+R26+S26+T26+U26-W26-X26 -> 0 | Y26: JOSE J
A27: ESPECIALISTA DE MANTTO ELECTRICO | E27: hr | G27: 237.68 | H27: =F27*G27 -> 0 | J27: 277.97 | K27: =I27*J27 -> 0 | M27: 538.84 | N27: =L27*M27 -> 0 | V27: =+O27+P27+Q27+R27+S27+T27+U27-W27-X27 -> 0
A28: TECNICO EN INSTRUMENTACION | E28: hr | G28: 368.59 | H28: =F28*G28 -> 0 | J28: 221.7 | K28: =I28*J28 -> 0 | M28: 538.84 | N28: =L28*M28 -> 0 | V28: =+O28+P28+Q28+R28+S28+T28+U28-W28-X28 -> 0
A29: OFICIAL ELECTRICO/ELECTROMECANICO | E29: hr | F29: =9.5*5 -> 47.5 | G29: 143 | H29: =F29*G29 -> 6792.5 | I29: 6 | J29: 165 | K29: =I29*J29 -> 990 | M29: 277.56 | N29: =L29*M29 -> 0 | V29: =+O29+P29+Q29+R29+S29+T29+U29-W29-X29 -> 0
A30: ASISTENTE DE DISEÑO | E30: hr | G30: 190.25 | H30: =F30*G30 -> 0 | J30: 221.7 | K30: =I30*J30 -> 0 | M30: 297.41 | N30: =L30*M30 -> 0 | V30: =+O30+P30+Q30+R30+S30+T30+U30-W30-X30 -> 0
A31: ELECTRICISTA -B | E31: hr | F31: =9.5*5 -> 47.5 | G31: 119.54 | H31: =F31*G31 -> 5678.15 | I31: 6 | J31: 137.92 | K31: =I31*J31 -> 827.52 | M31: 0 | N31: =L31*M31 -> 0 | V31: =+O31+P31+Q31+R31+S31+T31+U31-W31-X31 -> 0 | Y31: GERMAN
A32: ELECTRICISTA -A | E32: hr | G32: 119.54 | H32: =F32*G32 -> 0 | J32: 137.92 | K32: =I32*J32 -> 0 | M32: 240.95 | N32: =L32*M32 -> 0 | V32: =+O32+P32+Q32+R32+S32+T32+U32-W32-X32 -> 0 | Y32: OSCAR-OSWALDO JIM
A33: AUXILIAR TECNICO | E33: hr | G33: 106.45 | H33: =F33*G33 -> 0 | J33: 137.92 | K33: =I33*J33 -> 0 | M33: 260.95 | N33: =L33*M33 -> 0 | V33: =+O33+P33+Q33+R33+S33+T33+U33-W33-X33 -> 0
A34: AYTE ELECTRICO - B | E34: hr | G34: 106.45 | H34: =F34*G34 -> 0 | J34: 122.4 | K34: =I34*J34 -> 0 | N34: =L34*M34 -> 0 | V34: =+O34+P34+Q34+R34+S34+T34+U34-W34-X34 -> 0
A35: AYTE DE ELECTR. -A | E35: hr | G35: 106.54 | H35: =F35*G35 -> 0 | J35: 122.4 | K35: =I35*J35 -> 0 | M35: 198.17 | N35: =L35*M35 -> 0 | V35: =+O35+P35+Q35+R35+S35+T35+U35-W35-X35 -> 0 | Y35: URIEL-GUILLERMO-ENRIQUE
A36: AYTE GENERAL | E36: hr | G36: 100.42 | H36: =F36*G36 -> 0 | J36: 122.4 | K36: =I36*J36 -> 0 | M36: 0 | N36: =L36*M36 -> 0 | V36: =+O36+P36+Q36+R36+S36+T36+U36-W36-X36 -> 0
A37: PROFESIONISTA | E37: hr | G37: 209.25 | H37: =F37*G37 -> 0 | J37: 406 | K37: =I37*J37 -> 0 | M37: 564.86 | N37: =L37*M37 -> 0 | V37: 0 | Y37: O.ZARCO-GABRIEL
A38: COORDINADOR DE OPERACIONES | E38: hr | G38: 0 | H38: =F38*G38 -> 0 | J38: 0 | K38: =I38*J38 -> 0 | M38: 0 | N38: =L38*M38 -> 0 | V38: =+O38+P38+Q38+R38+S38+T38+U38-W38-X38 -> 0
A39: INGENIERIA Y SOPORTE TEC. | E39: hr | G39: 339.75 | H39: =F39*G39 -> 0 | J39: 325.79 | K39: =I39*J39 -> 0 | M39: 488.68 | N39: =L39*M39 -> 0 | V39: =+O39+P39+Q39+R39+S39+T39+U39-W39-X39 -> 0
A40: INGENIERO DE SUBESTACIONES | E40: hr | G40: 339.75 | H40: =F40*G40 -> 0 | J40: 325.79 | K40: =I40*J40 -> 0 | M40: 488.68 | N40: =L40*M40 -> 0 | V40: =+O40+P40+Q40+R40+S40+T40+U40-W40-X40 -> 0
A41: INGENIERO DE PRUEBAS ELECTRICAS | E41: hr | G41: 339.75 | H41: =F41*G41 -> 0 | J41: 325.79 | K41: =I41*J41 -> 0 | M41: 488.68 | N41: =L41*M41 -> 0 | V41: =+O41+P41+Q41+R41+S41+T41+U41-W41-X41 -> 0
...

Sheet MAT (1)
A1: I M M E E S. A. D E C. V.
A2: A N A L I S I S D E P R E C I O U N I T A R I O
A3: COTIZACION:
A4: FECHA:
A5: PARTIDA 1
A6: REV-06-feb-2021
A7: MATERIALES.
A8: DESCRIPCION | E8: UNIDAD | F8: CANT. | G8: P.U. | H8: IMPORTE | J8: MATERIALES
A9: charola tipo escalera perfil Z para servicio pesado de 30" | E9: Pza | F9: 6 | G9: 2540.01 | H9: =G9*F9 -> 15240.06
A10: tapa para charola tipo escalera de 30". | E10: Pza | G10: 1001 | H10: =G10*F10 -> 0
A11: curva vertical exterior de 90° para charola tipo escalera de 30 | E11: Pza | G11: 450.5 | H11: =G11*F11 -> 0
A12: tapa para curva vertical exterior de 90° para charola tipo escalera para servicio pesado de 30" | E12: Pza | G12: 136.52 | H12: =G12*F12 -> 0
A13: curva horizontal de 90° para charola tipo escalera para servicio pesado de 30" | E13: Pza | G13: 620.97 | H13: =G13*F13 -> 0
A14: base de unicanal solido galvanizado de 4x4 | E14: Pza | G14: 382.32 | H14: =G14*F14 -> 0
A15: tornilleria galvanizada | E15: Pza | G15: 200 | H15: =G15*F15 -> 0
A16: varilla roscada galvanizada de 3 metros de largo X 1/2" | E16: Pza | G16: 70 | H16: =G16*F16 -> 0
A17: conector de charola para servicio pesado de 30 | E17: Pza | G17: 467.05 | H17: =G17*F17 -> 0
A18: zapata ponchable para cable de cobre cañon largo calibre 500 KCM, con 2 ojillos de 1/2 | E18: Pza | G18: 495.41 | H18: =G18*F18 -> 0
A19: manga termocontractil para nivel de aislamiento de 600 V, en calibre 500 KCM. | E19: Pza | G19: 212.43 | H19: =G19*F19 -> 0
A20: sistema corta fuego con lana mineral y compuesto SF-ONE. | E20: Pza | G20: 698.25 | H20: =G20*F20 -> 0
A21: cuellos de lona flexibles en gargantas primarias de generador electrico | E21: Pza | G21: 160.08 | H21: =G21*F21 -> 0
A22: cable de cobre THW calibre 12 AWG | E22: mt | G22: 12.63 | H22: =G22*F22 -> 0 | L22: NOTA: CONSIDERAR LA JORNADA DE 8.0 HORAS, AUNQUE EN IMMEE SE TRABAJE JORNADA LARGA CONVENIDA, Y DOMINGO DESCANSO
A23: tapones para unicanal de 4x4 y varilla roscada | E23: Pza | G23: 27.6 | H23: =G23*F23 -> 0
A24: tapones para esparrago | E24: Pza | G24: 70.34 | H24: =G24*F24 -> 0
A25: cable de cobre 500 mts THW LS calibre 500 MCM | E25: CARRETE | G25: 897.84 | H25: =G25*F25 -> 0
A26: Renta de una plataforma de elevacion | E26: Pza | F26: 0 | G26: 25000 | H26: =G26*F26 -> 0 | I26: =H26*1.455 -> 0
G27: SUBT 1 | H27: =SUM(H9:H26) -> 15240.06
A29: MANO DE OBRA SIN INDIRECTOS | O29: HORARIOS DE TRABAJO | V29: HORAS RESULTANTES | Y29: PERSONAL PEOPUESTO
A30: PERSONAL. | E30: UNIDAD | F30: CANT. | G30: HORA NORMAL | H30: IMPORTE | I30: CANT. | J30: Hr. Extra | K30: IMPORTE | L30: CANT. | M30: Dom, ó Fest.TRIPLE | N30: IMPORTE | O30: L | P30: M | Q30: MI | R30: J | S30: V | T30: S | U30: D | V30: N | W30: D | X30: T
A31: SUPERVISOR DE SEGURIDAD CERTIFICADO | E31: hr | G31: 390.39 | H31: =F31*G31 -> 0 | J31: 358.81 | K31: =I31*J31 -> 0 | M31: 538.27 | N31: =L31*M31 -> 0 | V31: =+O31+P31+Q31+R31+S31+T31+U31-W31-X31 -> 0
A32: SUPERVISOR DE SEGURIDAD | E32: hr | G32: 243.45 | H32: =F32*G32 -> 0 | J32: 211.59 | K32: =I32*J32 -> 0 | M32: 317.39 | N32: =L32*M32 -> 0 | V32: =+O32+P32+Q32+R32+S32+T32+U32-W32-X32 -> 0 | Y32: OSWALDO Z-GABRIEL
A33: SUPERVISOR ELECTRICO | E33: hr | G33: 390.39 | H33: =F33*G33 -> 0 | J33: 358.81 | K33: =I33*J33 -> 0 | M33: 538.22 | N33: =L33*M33 -> 0 | V33: =+O33+P33+Q33+R33+S33+T33+U33-W33-X33 -> 0 | Y33: ADRIAN
A34: TECNICO DE PRUEBAS ELECTRICAS | E34: hr | G34: 231.67 | H34: =F34*G34 -> 0 | J34: 197.63 | K34: =I34*J34 -> 0 | M34: 296.45 | N34: =L34*M34 -> 0 | V34: =+O34+P34+Q34+R34+S34+T34+U34-W34-X34 -> 0 | Y34: HECTOR
A35: CABO OBRA ELECTRICA | E35: hr | G35: 310.62 | H35: =F35*G35 -> 0 | J35: 291.24 | K35: =I35*J35 -> 0 | M35: 436.87 | N35: =L35*M35 -> 0 | V35: =+O35+P35+Q35+R35+S35+T35+U35-W35-X35 -> 0
A36: LINIERO | E36: hr | G36: 310.62 | H36: =F36*G36 -> 0 | J36: 291.24 | K36: =I36*J36 -> 0 | M36: 436.87 | N36: =L36*M36 -> 0 | V36: =+O36+P36+Q36+R36+S36+T36+U36-W36-X36 -> 0 | Y36: JOSE J
A37: ESPECIALISTA DE MANTTO ELECTRICO | E37: hr | H37: =F37*G37 -> 0 | J37: 0 | K37: =I37*J37 -> 0 | M37: 0 | N37: =L37*M37 -> 0 | V37: =+O37+P37+Q37+R37+S37+T37+U37-W37-X37 -> 0
A38: TECNICO EN INSTRUMENTACION | E38: hr | G38: 199.6 | H38: =F38*G38 -> 0 | J38: 159.6 | K38: =I38*J38 -> 0 | M38: 239.4 | N38: =L38*M38 -> 0 | V38: =+O38+P38+Q38+R38+S38+T38+U38-W38-X38 -> 0
A39: OFICIAL ELECTRICO/ELECTROMECANICO | E39: hr | G39: 199.6 | H39: =F39*G39 -> 0 | J39: 159.6 | K39: =I39*J39 -> 0 | M39: 239.4 | N39: =L39*M39 -> 0 | V39: =+O39+P39+Q39+R39+S39+T39+U39-W39-X39 -> 0
A40: ASISTENTE DE DISEÑO | E40: hr | G40: 199.6 | H40: =F40*G40 -> 0 | J40: 159.6 | K40: =I40*J40 -> 0 | M40: 239.4 | N40: =L40*M40 -> 0 | V40: =+O40+P40+Q40+R40+S40+T40+U40-W40-X40 -> 0
A41: ELECTRICISTA -B | E41: hr | G41: 211.15 | H41: =F41*G41 -> 0 | J41: 173.29 | K41: =I41*J41 -> 0 | M41: 259.94 | N41: =L41*M41 -> 0 | V41: =+O41+P41+Q41+R41+S41+T41+U41-W41-X41 -> 0 | Y41: GERMAN
...

Sheet M0 (1)
A1: I M M E E S. A. D E C. V.
A2: A N A L I S I S D E P R E C I O U N I T A R I O
A3: COTIZACION:
A4: FECHA:
A5: PARTIDA 1
A6: REV-06-feb-2021
A7: MATERIALES.
A8: DESCRIPCION | E8: UNIDAD | F8: CANT. | G8: P.U. | H8: IMPORTE | J8: MANO DE OBRA
A9: Consumible | E9: Pza | H9: =G9*F9 -> 0
E10: Pza | H10: =G10*F10 -> 0
E11: Pza | H11: =G11*F11 -> 0
E12: Pza | H12: =G12*F12 -> 0
E13: Pza | H13: =G13*F13 -> 0
E14: Pza | H14: =G14*F14 -> 0
E15: Pza | H15: =G15*F15 -> 0
E16: Pza | H16: =G16*F16 -> 0 | I16: =H16*1.455 -> 0
G17: SUBT 1 | H17: =SUM(H9:H16) -> 0
A19: MANO DE OBRA SIN INDIRECTOS | O19: HORARIOS DE TRABAJO | V19: HORAS RESULTANTES | Y19: PERSONAL PEOPUESTO
A20: PERSONAL. | E20: UNIDAD | F20: CANT. | G20: HORA NORMAL | H20: IMPORTE | I20: CANT. | J20: Hr. Extra | K20: IMPORTE | L20: CANT. | M20: Dom, ó Fest.TRIPLE | N20: IMPORTE | O20: L | P20: M | Q20: MI | R20: J | S20: V | T20: S | U20: D | V20: N | W20: D | X20: T
A21: SUPERVISOR DE SEGURIDAD CERTIFICADO | E21: hr | G21: 390.39 | H21: =F21*G21 -> 0 | J21: 358.81 | K21: =I21*J21 -> 0 | M21: 538.27 | N21: =L21*M21 -> 0 | V21: =+O21+P21+Q21+R21+S21+T21+U21-W21-X21 -> 0
A22: SUPERVISOR DE SEGURIDAD | E22: hr | F22: 8 | G22: 317.98 | H22: =F22*G22 -> 2543.84 | I22: 2 | J22: 326.25 | K22: =I22*J22 -> 652.5 | M22: 489.37 | N22: =L22*M22 -> 0 | V22: =+O22+P22+Q22+R22+S22+T22+U22-W22-X22 -> 0 | Y22: OSWALDO Z-GABRIEL
A23: SUPERVISOR ELECTRICO | E23: hr | F23: 8 | G23: 237.68 | H23: =F23*G23 -> 1901.44 | I23: 2 | J23: 358.81 | K23: =I23*J23 -> 717.62 | M23: 538.22 | N23: =L23*M23 -> 0 | V23: =+O23+P23+Q23+R23+S23+T23+U23-W23-X23 -> 0 | Y23: ADRIAN
A24: TECNICO DE PRUEBAS ELECTRICAS | E24: hr | G24: 317.98 | H24: =F24*G24 -> 0 | J24: 244.27 | K24: =I24*J24 -> 0 | M24: 489.37 | N24: =L24*M24 -> 0 | V24: =+O24+P24+Q24+R24+S24+T24+U24-W24-X24 -> 0 | Y24: HECTOR
A25: CABO OBRA ELECTRICA | E25: hr | G25: 310.62 | H25: =F25*G25 -> 0 | J25: 335 | K25: =I25*J25 -> 0 | M25: 436.87 | N25: =L25*M25 -> 0 | V25: =+O25+P25+Q25+R25+S25+T25+U25-W25-X25 -> 0
A26: LINIERO | E26: hr | G26: 209.25 | H26: =F26*G26 -> 0 | J26: 221.7 | K26: =I26*J26 -> 0 | M26: 437.63 | N26: =L26*M26 -> 0 | V26: =+O26+P26+Q26+R26+S26+T26+U26-W26-X26 -> 0 | Y26: JOSE J
A27: ESPECIALISTA DE MANTTO ELECTRICO | E27: hr | G27: 237.68 | H27: =F27*G27 -> 0 | J27: 277.97 | K27: =I27*J27 -> 0 | M27: 538.84 | N27: =L27*M27 -> 0 | V27: =+O27+P27+Q27+R27+S27+T27+U27-W27-X27 -> 0
A28: TECNICO EN INSTRUMENTACION | E28: hr | G28: 368.59 | H28: =F28*G28 -> 0 | J28: 221.7 | K28: =I28*J28 -> 0 | M28: 538.84 | N28: =L28*M28 -> 0 | V28: =+O28+P28+Q28+R28+S28+T28+U28-W28-X28 -> 0
A29: OFICIAL ELECTRICO/ELECTROMECANICO | E29: hr | F29: 8 | G29: 190.22 | H29: =F29*G29 -> 1521.76 | I29: 2 | J29: 221.7 | K29: =I29*J29 -> 443.4 | M29: 277.56 | N29: =L29*M29 -> 0 | V29: =+O29+P29+Q29+R29+S29+T29+U29-W29-X29 -> 0
A30: ASISTENTE DE DISEÑO | E30: hr | G30: 190.25 | H30: =F30*G30 -> 0 | J30: 221.7 | K30: =I30*J30 -> 0 | M30: 297.41 | N30: =L30*M30 -> 0 | V30: =+O30+P30+Q30+R30+S30+T30+U30-W30-X30 -> 0
A31: ELECTRICISTA -B | E31: hr | G31: 119.54 | H31: =F31*G31 -> 0 | J31: 137.92 | K31: =I31*J31 -> 0 | M31: 0 | N31: =L31*M31 -> 0 | V31: =+O31+P31+Q31+R31+S31+T31+U31-W31-X31 -> 0 | Y31: GERMAN
A32: ELECTRICISTA -A | E32: hr | G32: 119.54 | H32: =F32*G32 -> 0 | J32: 137.92 | K32: =I32*J32 -> 0 | M32: 240.95 | N32: =L32*M32 -> 0 | V32: =+O32+P32+Q32+R32+S32+T32+U32-W32-X32 -> 0 | Y32: OSCAR-OSWALDO JIM
A33: AUXILIAR TECNICO | E33: hr | G33: 106.45 | H33: =F33*G33 -> 0 | J33: 137.92 | K33: =I33*J33 -> 0 | M33: 260.95 | N33: =L33*M33 -> 0 | V33: =+O33+P33+Q33+R33+S33+T33+U33-W33-X33 -> 0
A34: AYTE ELECTRICO - B | E34: hr | F34: 8 | G34: 106.45 | H34: =F34*G34 -> 851.6 | I34: 2 | J34: 122.4 | K34: =I34*J34 -> 244.8 | N34: =L34*M34 -> 0 | V34: =+O34+P34+Q34+R34+S34+T34+U34-W34-X34 -> 0
A35: AYTE DE ELECTR. -A | E35: hr | G35: 106.54 | H35: =F35*G35 -> 0 | J35: 122.4 | K35: =I35*J35 -> 0 | M35: 198.17 | N35: =L35*M35 -> 0 | V35: =+O35+P35+Q35+R35+S35+T35+U35-W35-X35 -> 0 | Y35: URIEL-GUILLERMO-ENRIQUE
A36: AYTE GENERAL | E36: hr | G36: 100.42 | H36: =F36*G36 -> 0 | J36: 122.4 | K36: =I36*J36 -> 0 | M36: 0 | N36: =L36*M36 -> 0 | V36: =+O36+P36+Q36+R36+S36+T36+U36-W36-X36 -> 0
A37: PROFESIONISTA | E37: hr | G37: 209.25 | H37: =F37*G37 -> 0 | J37: 406 | K37: =I37*J37 -> 0 | M37: 564.86 | N37: =L37*M37 -> 0 | V37: 0 | Y37: O.ZARCO-GABRIEL
A38: COORDINADOR DE OPERACIONES | E38: hr | G38: 0 | H38: =F38*G38 -> 0 | J38: 0 | K38: =I38*J38 -> 0 | M38: 0 | N38: =L38*M38 -> 0 | V38: =+O38+P38+Q38+R38+S38+T38+U38-W38-X38 -> 0
A39: INGENIERIA Y SOPORTE TEC. | E39: hr | G39: 339.75 | H39: =F39*G39 -> 0 | J39: 325.79 | K39: =I39*J39 -> 0 | M39: 488.68 | N39: =L39*M39 -> 0 | V39: =+O39+P39+Q39+R39+S39+T39+U39-W39-X39 -> 0
A40: INGENIERO DE SUBESTACIONES | E40: hr | G40: 339.75 | H40: =F40*G40 -> 0 | J40: 325.79 | K40: =I40*J40 -> 0 | M40: 488.68 | N40: =L40*M40 -> 0 | V40: =+O40+P40+Q40+R40+S40+T40+U40-W40-X40 -> 0
A41: INGENIERO DE PRUEBAS ELECTRICAS | E41: hr | G41: 339.75 | H41: =F41*G41 -> 0 | J41: 325.79 | K41: =I41*J41 -> 0 | M41: 488.68 | N41: =L41*M41 -> 0 | V41: =+O41+P41+Q41+R41+S41+T41+U41-W41-X41 -> 0
...

Sheet MAT (2)
A1: I M M E E S. A. D E C. V.
A2: A N A L I S I S D E P R E C I O U N I T A R I O
A3: COTIZACION:
A4: FECHA:
A5: PARTIDA 1
A6: REV-06-feb-2021
A7: MATERIALES.
A8: DESCRIPCION | E8: UNIDAD | F8: CANT. | G8: P.U. | H8: IMPORTE | J8: MATERIALES
A9: charola tipo escalera perfil Z para servicio pesado de 30" | E9: Pza | G9: 2540.01 | H9: =G9*F9 -> 0
A10: tapa para charola tipo escalera de 30". | E10: Pza | F10: 6 | G10: 1001 | H10: =G10*F10 -> 6006
A11: curva vertical exterior de 90° para charola tipo escalera de 30 | E11: Pza | G11: 450.5 | H11: =G11*F11 -> 0
A12: tapa para curva vertical exterior de 90° para charola tipo escalera para servicio pesado de 30" | E12: Pza | G12: 136.52 | H12: =G12*F12 -> 0
A13: curva horizontal de 90° para charola tipo escalera para servicio pesado de 30" | E13: Pza | G13: 620.97 | H13: =G13*F13 -> 0
A14: base de unicanal solido galvanizado de 4x4 | E14: Pza | G14: 382.32 | H14: =G14*F14 -> 0
A15: tornilleria galvanizada | E15: Pza | G15: 200 | H15: =G15*F15 -> 0
A16: varilla roscada galvanizada de 3 metros de largo X 1/2" | E16: Pza | G16: 70 | H16: =G16*F16 -> 0
A17: conector de charola para servicio pesado de 30 | E17: Pza | G17: 467.05 | H17: =G17*F17 -> 0
A18: zapata ponchable para cable de cobre cañon largo calibre 500 KCM, con 2 ojillos de 1/2 | E18: Pza | G18: 495.41 | H18: =G18*F18 -> 0
A19: manga termocontractil para nivel de aislamiento de 600 V, en calibre 500 KCM. | E19: Pza | G19: 212.43 | H19: =G19*F19 -> 0
A20: sistema corta fuego con lana mineral y compuesto SF-ONE. | E20: Pza | G20: 698.25 | H20: =G20*F20 -> 0
A21: cuellos de lona flexibles en gargantas primarias de generador electrico | E21: Pza | G21: 160.08 | H21: =G21*F21 -> 0
A22: cable de cobre THW calibre 12 AWG | E22: mt | G22: 12.63 | H22: =G22*F22 -> 0 | L22: NOTA: CONSIDERAR LA JORNADA DE 8.0 HORAS, AUNQUE EN IMMEE SE TRABAJE JORNADA LARGA CONVENIDA, Y DOMINGO DESCANSO
A23: tapones para unicanal de 4x4 y varilla roscada | E23: Pza | G23: 27.6 | H23: =G23*F23 -> 0
A24: tapones para esparrago | E24: Pza | G24: 70.34 | H24: =G24*F24 -> 0
A25: Renta de una plataforma de elevacion | E25: Pza | F25: 0 | G25: 25000 | H25: =G25*F25 -> 0
A26: CONSUMIBLES | E26: Pza | F26: 1 | G26: 200 | H26: =G26*F26 -> 200
G27: SUBT 1 | H27: =SUM(H9:H26) -> 6206
A29: MANO DE OBRA SIN INDIRECTOS | O29: HORARIOS DE TRABAJO | V29: HORAS RESULTANTES | Y29: PERSONAL PEOPUESTO
A30: PERSONAL. | E30: UNIDAD | F30: CANT. | G30: HORA NORMAL | H30: IMPORTE | I30: CANT. | J30: Hr. Extra | K30: IMPORTE | L30: CANT. | M30: Dom, ó Fest.TRIPLE | N30: IMPORTE | O30: L | P30: M | Q30: MI | R30: J | S30: V | T30: S | U30: D | V30: N | W30: D | X30: T
A31: SUPERVISOR DE SEGURIDAD CERTIFICADO | E31: hr | G31: 390.39 | H31: =F31*G31 -> 0 | J31: 358.81 | K31: =I31*J31 -> 0 | M31: 538.27 | N31: =L31*M31 -> 0 | V31: =+O31+P31+Q31+R31+S31+T31+U31-W31-X31 -> 0
A32: SUPERVISOR DE SEGURIDAD | E32: hr | G32: 243.45 | H32: =F32*G32 -> 0 | J32: 211.59 | K32: =I32*J32 -> 0 | M32: 317.39 | N32: =L32*M32 -> 0 | V32: =+O32+P32+Q32+R32+S32+T32+U32-W32-X32 -> 0 | Y32: OSWALDO Z-GABRIEL
A33: SUPERVISOR ELECTRICO | E33: hr | G33: 390.39 | H33: =F33*G33 -> 0 | J33: 358.81 | K33: =I33*J33 -> 0 | M33: 538.22 | N33: =L33*M33 -> 0 | V33: =+O33+P33+Q33+R33+S33+T33+U33-W33-X33 -> 0 | Y33: ADRIAN
A34: TECNICO DE PRUEBAS ELECTRICAS | E34: hr | G34: 231.67 | H34: =F34*G34 -> 0 | J34: 197.63 | K34: =I34*J34 -> 0 | M34: 296.45 | N34: =L34*M34 -> 0 | V34: =+O34+P34+Q34+R34+S34+T34+U34-W34-X34 -> 0 | Y34: HECTOR
A35: CABO OBRA ELECTRICA | E35: hr | G35: 310.62 | H35: =F35*G35 -> 0 | J35: 291.24 | K35: =I35*J35 -> 0 | M35: 436.87 | N35: =L35*M35 -> 0 | V35: =+O35+P35+Q35+R35+S35+T35+U35-W35-X35 -> 0
A36: LINIERO | E36: hr | G36: 310.62 | H36: =F36*G36 -> 0 | J36: 291.24 | K36: =I36*J36 -> 0 | M36: 436.87 | N36: =L36*M36 -> 0 | V36: =+O36+P36+Q36+R36+S36+T36+U36-W36-X36 -> 0 | Y36: JOSE J
A37: ESPECIALISTA DE MANTTO ELECTRICO | E37: hr | H37: =F37*G37 -> 0 | J37: 0 | K37: =I37*J37 -> 0 | M37: 0 | N37: =L37*M37 -> 0 | V37: =+O37+P37+Q37+R37+S37+T37+U37-W37-X37 -> 0
A38: TECNICO EN INSTRUMENTACION | E38: hr | G38: 199.6 | H38: =F38*G38 -> 0 | J38: 159.6 | K38: =I38*J38 -> 0 | M38: 239.4 | N38: =L38*M38 -> 0 | V38: =+O38+P38+Q38+R38+S38+T38+U38-W38-X38 -> 0
A39: OFICIAL ELECTRICO/ELECTROMECANICO | E39: hr | G39: 199.6 | H39: =F39*G39 -> 0 | J39: 159.6 | K39: =I39*J39 -> 0 | M39: 239.4 | N39: =L39*M39 -> 0 | V39: =+O39+P39+Q39+R39+S39+T39+U39-W39-X39 -> 0
A40: ASISTENTE DE DISEÑO | E40: hr | G40: 199.6 | H40: =F40*G40 -> 0 | J40: 159.6 | K40: =I40*J40 -> 0 | M40: 239.4 | N40: =L40*M40 -> 0 | V40: =+O40+P40+Q40+R40+S40+T40+U40-W40-X40 -> 0
A41: ELECTRICISTA -B | E41: hr | G41: 211.15 | H41: =F41*G41 -> 0 | J41: 173.29 | K41: =I41*J41 -> 0 | M41: 259.94 | N41: =L41*M41 -> 0 | V41: =+O41+P41+Q41+R41+S41+T41+U41-W41-X41 -> 0 | Y41: GERMAN
...

Sheet M0 (2)
A1: I M M E E S. A. D E C. V.
A2: A N A L I S I S D E P R E C I O U N I T A R I O
A3: COTIZACION:
A4: FECHA:
A5: PARTIDA 1
A6: REV-06-feb-2021
A7: MATERIALES.
A8: DESCRIPCION | E8: UNIDAD | F8: CANT. | G8: P.U. | H8: IMPORTE | J8: MANO DE OBRA
A9: Consumible | E9: Pza | H9: =G9*F9 -> 0
E10: Pza | H10: =G10*F10 -> 0
E11: Pza | H11: =G11*F11 -> 0
E12: Pza | H12: =G12*F12 -> 0
E13: Pza | H13: =G13*F13 -> 0
E14: Pza | H14: =G14*F14 -> 0
E15: Pza | H15: =G15*F15 -> 0
E16: Pza | H16: =G16*F16 -> 0 | I16: =H16*1.455 -> 0
G17: SUBT 1 | H17: =SUM(H9:H16) -> 0
A19: MANO DE OBRA SIN INDIRECTOS | O19: HORARIOS DE TRABAJO | V19: HORAS RESULTANTES | Y19: PERSONAL PEOPUESTO
A20: PERSONAL. | E20: UNIDAD | F20: CANT. | G20: HORA NORMAL | H20: IMPORTE | I20: CANT. | J20: Hr. Extra | K20: IMPORTE | L20: CANT. | M20: Dom, ó Fest.TRIPLE | N20: IMPORTE | O20: L | P20: M | Q20: MI | R20: J | S20: V | T20: S | U20: D | V20: N | W20: D | X20: T
A21: SUPERVISOR DE SEGURIDAD CERTIFICADO | E21: hr | G21: 390.39 | H21: =F21*G21 -> 0 | J21: 358.81 | K21: =I21*J21 -> 0 | M21: 538.27 | N21: =L21*M21 -> 0 | V21: =+O21+P21+Q21+R21+S21+T21+U21-W21-X21 -> 0
A22: SUPERVISOR DE SEGURIDAD | E22: hr | F22: 1 | G22: 317.98 | H22: =F22*G22 -> 317.98 | J22: 326.25 | K22: =I22*J22 -> 0 | M22: 489.37 | N22: =L22*M22 -> 0 | V22: =+O22+P22+Q22+R22+S22+T22+U22-W22-X22 -> 0 | Y22: OSWALDO Z-GABRIEL
A23: SUPERVISOR ELECTRICO | E23: hr | F23: 1 | G23: 237.68 | H23: =F23*G23 -> 237.68 | J23: 358.81 | K23: =I23*J23 -> 0 | M23: 538.22 | N23: =L23*M23 -> 0 | V23: =+O23+P23+Q23+R23+S23+T23+U23-W23-X23 -> 0 | Y23: ADRIAN
A24: TECNICO DE PRUEBAS ELECTRICAS | E24: hr | G24: 317.98 | H24: =F24*G24 -> 0 | J24: 244.27 | K24: =I24*J24 -> 0 | M24: 489.37 | N24: =L24*M24 -> 0 | V24: =+O24+P24+Q24+R24+S24+T24+U24-W24-X24 -> 0 | Y24: HECTOR
A25: CABO OBRA ELECTRICA | E25: hr | G25: 310.62 | H25: =F25*G25 -> 0 | J25: 335 | K25: =I25*J25 -> 0 | M25: 436.87 | N25: =L25*M25 -> 0 | V25: =+O25+P25+Q25+R25+S25+T25+U25-W25-X25 -> 0
A26: LINIERO | E26: hr | G26: 209.25 | H26: =F26*G26 -> 0 | J26: 221.7 | K26: =I26*J26 -> 0 | M26: 437.63 | N26: =L26*M26 -> 0 | V26: =+O26+P26+Q26+R26+S26+T26+U26-W26-X26 -> 0 | Y26: JOSE J
A27: ESPECIALISTA DE MANTTO ELECTRICO | E27: hr | G27: 237.68 | H27: =F27*G27 -> 0 | J27: 277.97 | K27: =I27*J27 -> 0 | M27: 538.84 | N27: =L27*M27 -> 0 | V27: =+O27+P27+Q27+R27+S27+T27+U27-W27-X27 -> 0
A28: TECNICO EN INSTRUMENTACION | E28: hr | G28: 368.59 | H28: =F28*G28 -> 0 | J28: 221.7 | K28: =I28*J28 -> 0 | M28: 538.84 | N28: =L28*M28 -> 0 | V28: =+O28+P28+Q28+R28+S28+T28+U28-W28-X28 -> 0
A29: OFICIAL ELECTRICO/ELECTROMECANICO | E29: hr | F29: 2 | G29: 190.22 | H29: =F29*G29 -> 380.44 | J29: 165 | K29: =I29*J29 -> 0 | M29: 277.56 | N29: =L29*M29 -> 0 | V29: =+O29+P29+Q29+R29+S29+T29+U29-W29-X29 -> 0
A30: ASISTENTE DE DISEÑO | E30: hr | G30: 190.25 | H30: =F30*G30 -> 0 | J30: 221.7 | K30: =I30*J30 -> 0 | M30: 297.41 | N30: =L30*M30 -> 0 | V30: =+O30+P30+Q30+R30+S30+T30+U30-W30-X30 -> 0
A31: ELECTRICISTA -B | E31: hr | G31: 119.54 | H31: =F31*G31 -> 0 | J31: 137.92 | K31: =I31*J31 -> 0 | M31: 0 | N31: =L31*M31 -> 0 | V31: =+O31+P31+Q31+R31+S31+T31+U31-W31-X31 -> 0 | Y31: GERMAN
A32: ELECTRICISTA -A | E32: hr | F32: 2 | G32: 119.54 | H32: =F32*G32 -> 239.08 | J32: 137.92 | K32: =I32*J32 -> 0 | M32: 240.95 | N32: =L32*M32 -> 0 | V32: =+O32+P32+Q32+R32+S32+T32+U32-W32-X32 -> 0 | Y32: OSCAR-OSWALDO JIM
A33: AUXILIAR TECNICO | E33: hr | G33: 106.45 | H33: =F33*G33 -> 0 | J33: 137.92 | K33: =I33*J33 -> 0 | M33: 260.95 | N33: =L33*M33 -> 0 | V33: =+O33+P33+Q33+R33+S33+T33+U33-W33-X33 -> 0
A34: AYTE ELECTRICO - B | E34: hr | F34: 2 | G34: 106.45 | H34: =F34*G34 -> 212.9 | J34: 122.4 | K34: =I34*J34 -> 0 | N34: =L34*M34 -> 0 | V34: =+O34+P34+Q34+R34+S34+T34+U34-W34-X34 -> 0
A35: AYTE DE ELECTR. -A | E35: hr | G35: 106.54 | H35: =F35*G35 -> 0 | J35: 122.4 | K35: =I35*J35 -> 0 | M35: 198.17 | N35: =L35*M35 -> 0 | V35: =+O35+P35+Q35+R35+S35+T35+U35-W35-X35 -> 0 | Y35: URIEL-GUILLERMO-ENRIQUE
A36: AYTE GENERAL | E36: hr | G36: 100.42 | H36: =F36*G36 -> 0 | J36: 122.4 | K36: =I36*J36 -> 0 | M36: 0 | N36: =L36*M36 -> 0 | V36: =+O36+P36+Q36+R36+S36+T36+U36-W36-X36 -> 0
A37: PROFESIONISTA | E37: hr | G37: 209.25 | H37: =F37*G37 -> 0 | J37: 406 | K37: =I37*J37 -> 0 | M37: 564.86 | N37: =L37*M37 -> 0 | V37: 0 | Y37: O.ZARCO-GABRIEL
A38: COORDINADOR DE OPERACIONES | E38: hr | G38: 0 | H38: =F38*G38 -> 0 | J38: 0 | K38: =I38*J38 -> 0 | M38: 0 | N38: =L38*M38 -> 0 | V38: =+O38+P38+Q38+R38+S38+T38+U38-W38-X38 -> 0
A39: INGENIERIA Y SOPORTE TEC. | E39: hr | G39: 339.75 | H39: =F39*G39 -> 0 | J39: 325.79 | K39: =I39*J39 -> 0 | M39: 488.68 | N39: =L39*M39 -> 0 | V39: =+O39+P39+Q39+R39+S39+T39+U39-W39-X39 -> 0
A40: INGENIERO DE SUBESTACIONES | E40: hr | G40: 339.75 | H40: =F40*G40 -> 0 | J40: 325.79 | K40: =I40*J40 -> 0 | M40: 488.68 | N40: =L40*M40 -> 0 | V40: =+O40+P40+Q40+R40+S40+T40+U40-W40-X40 -> 0
A41: INGENIERO DE PRUEBAS ELECTRICAS | E41: hr | G41: 339.75 | H41: =F41*G41 -> 0 | J41: 325.79 | K41: =I41*J41 -> 0 | M41: 488.68 | N41: =L41*M41 -> 0 | V41: =+O41+P41+Q41+R41+S41+T41+U41-W41-X41 -> 0
...

Sheet MAT (3)
A1: I M M E E S. A. D E C. V.
A2: A N A L I S I S D E P R E C I O U N I T A R I O
A3: COTIZACION:
A4: FECHA:
A5: PARTIDA 1
A6: REV-06-feb-2021
A7: MATERIALES.
A8: DESCRIPCION | E8: UNIDAD | F8: CANT. | G8: P.U. | H8: IMPORTE | J8: MATERIALES
A9: charola tipo escalera perfil Z para servicio pesado de 30" | E9: Pza | G9: 2540.01 | H9: =G9*F9 -> 0
A10: tapa para charola tipo escalera de 30". | E10: Pza | G10: 1001 | H10: =G10*F10 -> 0
A11: curva vertical exterior de 90° para charola tipo escalera de 30 | E11: Pza | F11: 4 | G11: 450.5 | H11: =G11*F11 -> 1802
A12: tapa para curva vertical exterior de 90° para charola tipo escalera para servicio pesado de 30" | E12: Pza | G12: 136.52 | H12: =G12*F12 -> 0
A13: curva horizontal de 90° para charola tipo escalera para servicio pesado de 30" | E13: Pza | G13: 620.97 | H13: =G13*F13 -> 0
A14: base de unicanal solido galvanizado de 4x4 | E14: Pza | G14: 382.32 | H14: =G14*F14 -> 0
A15: tornilleria galvanizada | E15: Pza | G15: 200 | H15: =G15*F15 -> 0
A16: varilla roscada galvanizada de 3 metros de largo X 1/2" | E16: Pza | G16: 70 | H16: =G16*F16 -> 0
A17: conector de charola para servicio pesado de 30 | E17: Pza | G17: 467.05 | H17: =G17*F17 -> 0
A18: zapata ponchable para cable de cobre cañon largo calibre 500 KCM, con 2 ojillos de 1/2 | E18: Pza | G18: 495.41 | H18: =G18*F18 -> 0
A19: manga termocontractil para nivel de aislamiento de 600 V, en calibre 500 KCM. | E19: Pza | G19: 212.43 | H19: =G19*F19 -> 0
A20: tornillo tropicalizado de 1/2" con 2" de largo | E20: Pza | G20: 15 | H20: =G20*F20 -> 0
A21: tornillo tropicalizado de 1/2" con 4" de largo | E21: Pza | G21: 15 | H21: =G21*F21 -> 0
A22: sistema corta fuego con lana mineral y compuesto SF-ONE. | E22: Pza | G22: 698.25 | H22: =G22*F22 -> 0
A23: Materiales consumibles | E23: PZA | G23: 500 | H23: =G23*F23 -> 0
A24: cuellos de lona flexibles en gargantas primarias de generador electrico | E24: Pza | G24: 160.08 | H24: =G24*F24 -> 0
A25: cable de cobre THW calibre 12 AWG | E25: mt | G25: 12.63 | H25: =G25*F25 -> 0 | L25: NOTA: CONSIDERAR LA JORNADA DE 8.0 HORAS, AUNQUE EN IMMEE SE TRABAJE JORNADA LARGA CONVENIDA, Y DOMINGO DESCANSO
A26: tapones para unicanal de 4x4 y varilla roscada | E26: Pza | G26: 27.6 | H26: =G26*F26 -> 0
A27: tapones para esparrago | E27: Pza | G27: 70.34 | H27: =G27*F27 -> 0
A28: consumibles | E28: 1 | F28: 1 | G28: 300 | H28: =G28*F28 -> 300
A29: Renta de una plataforma de elevacion | E29: Pza | G29: 25000 | H29: =G29*F29 -> 0 | I29: =H29*1.455 -> 0
G30: SUBT 1 | H30: =SUM(H9:H29) -> 2102
A32: MANO DE OBRA SIN INDIRECTOS | O32: HORARIOS DE TRABAJO | V32: HORAS RESULTANTES | Y32: PERSONAL PEOPUESTO
A33: PERSONAL. | E33: UNIDAD | F33: CANT. | G33: HORA NORMAL | H33: IMPORTE | I33: CANT. | J33: Hr. Extra | K33: IMPORTE | L33: CANT. | M33: Dom, ó Fest.TRIPLE | N33: IMPORTE | O33: L | P33: M | Q33: MI | R33: J | S33: V | T33: S | U33: D | V33: N | W33: D | X33: T
A34: SUPERVISOR DE SEGURIDAD CERTIFICADO | E34: hr | G34: 390.39 | H34: =F34*G34 -> 0 | J34: 358.81 | K34: =I34*J34 -> 0 | M34: 538.27 | N34: =L34*M34 -> 0 | V34: =+O34+P34+Q34+R34+S34+T34+U34-W34-X34 -> 0
A35: SUPERVISOR DE SEGURIDAD | E35: hr | G35: 243.45 | H35: =F35*G35 -> 0 | J35: 211.59 | K35: =I35*J35 -> 0 | M35: 317.39 | N35: =L35*M35 -> 0 | V35: =+O35+P35+Q35+R35+S35+T35+U35-W35-X35 -> 0 | Y35: OSWALDO Z-GABRIEL
A36: SUPERVISOR ELECTRICO | E36: hr | G36: 390.39 | H36: =F36*G36 -> 0 | J36: 358.81 | K36: =I36*J36 -> 0 | M36: 538.22 | N36: =L36*M36 -> 0 | V36: =+O36+P36+Q36+R36+S36+T36+U36-W36-X36 -> 0 | Y36: ADRIAN
A37: TECNICO DE PRUEBAS ELECTRICAS | E37: hr | G37: 231.67 | H37: =F37*G37 -> 0 | J37: 197.63 | K37: =I37*J37 -> 0 | M37: 296.45 | N37: =L37*M37 -> 0 | V37: =+O37+P37+Q37+R37+S37+T37+U37-W37-X37 -> 0 | Y37: HECTOR
A38: CABO OBRA ELECTRICA | E38: hr | G38: 310.62 | H38: =F38*G38 -> 0 | J38: 291.24 | K38: =I38*J38 -> 0 | M38: 436.87 | N38: =L38*M38 -> 0 | V38: =+O38+P38+Q38+R38+S38+T38+U38-W38-X38 -> 0
A39: LINIERO | E39: hr | G39: 310.62 | H39: =F39*G39 -> 0 | J39: 291.24 | K39: =I39*J39 -> 0 | M39: 436.87 | N39: =L39*M39 -> 0 | V39: =+O39+P39+Q39+R39+S39+T39+U39-W39-X39 -> 0 | Y39: JOSE J
A40: ESPECIALISTA DE MANTTO ELECTRICO | E40: hr | H40: =F40*G40 -> 0 | J40: 0 | K40: =I40*J40 -> 0 | M40: 0 | N40: =L40*M40 -> 0 | V40: =+O40+P40+Q40+R40+S40+T40+U40-W40-X40 -> 0
A41: TECNICO EN INSTRUMENTACION | E41: hr | G41: 199.6 | H41: =F41*G41 -> 0 | J41: 159.6 | K41: =I41*J41 -> 0 | M41: 239.4 | N41: =L41*M41 -> 0 | V41: =+O41+P41+Q41+R41+S41+T41+U41-W41-X41 -> 0
...

Sheet M0  (3)
A1: I M M E E S. A. D E C. V.
A2: A N A L I S I S D E P R E C I O U N I T A R I O
A3: COTIZACION:
A4: FECHA:
A5: PARTIDA 1
A6: REV-06-feb-2021
A7: MATERIALES.
A8: DESCRIPCION | E8: UNIDAD | F8: CANT. | G8: P.U. | H8: IMPORTE | J8: MANO DE OBRA
A9: Consumible | E9: Pza | H9: =G9*F9 -> 0
E10: Pza | H10: =G10*F10 -> 0
E11: Pza | H11: =G11*F11 -> 0
E12: Pza | H12: =G12*F12 -> 0
E13: Pza | H13: =G13*F13 -> 0
E14: Pza | H14: =G14*F14 -> 0
E15: Pza | H15: =G15*F15 -> 0
E16: Pza | H16: =G16*F16 -> 0 | I16: =H16*1.455 -> 0
G17: SUBT 1 | H17: =SUM(H9:H16) -> 0
A19: MANO DE OBRA SIN INDIRECTOS | O19: HORARIOS DE TRABAJO | V19: HORAS RESULTANTES | Y19: PERSONAL PEOPUESTO
A20: PERSONAL. | E20: UNIDAD | F20: CANT. | G20: HORA NORMAL | H20: IMPORTE | I20: CANT. | J20: Hr. Extra | K20: IMPORTE | L20: CANT. | M20: Dom, ó Fest.TRIPLE | N20: IMPORTE | O20: L | P20: M | Q20: MI | R20: J | S20: V | T20: S | U20: D | V20: N | W20: D | X20: T
A21: SUPERVISOR DE SEGURIDAD CERTIFICADO | E21: hr | G21: 390.39 | H21: =F21*G21 -> 0 | J21: 358.81 | K21: =I21*J21 -> 0 | M21: 538.27 | N21: =L21*M21 -> 0 | V21: =+O21+P21+Q21+R21+S21+T21+U21-W21-X21 -> 0
A22: SUPERVISOR DE SEGURIDAD | E22: hr | F22: 4 | G22: 317.98 | H22: =F22*G22 -> 1271.92 | J22: 326.25 | K22: =I22*J22 -> 0 | M22: 489.37 | N22: =L22*M22 -> 0 | V22: =+O22+P22+Q22+R22+S22+T22+U22-W22-X22 -> 0 | Y22: OSWALDO Z-GABRIEL
A23: SUPERVISOR ELECTRICO | E23: hr | F23: 3 | G23: 237.68 | H23: =F23*G23 -> 713.04 | J23: 358.81 | K23: =I23*J23 -> 0 | M23: 538.22 | N23: =L23*M23 -> 0 | V23: =+O23+P23+Q23+R23+S23+T23+U23-W23-X23 -> 0 | Y23: ADRIAN
A24: TECNICO DE PRUEBAS ELECTRICAS | E24: hr | G24: 317.98 | H24: =F24*G24 -> 0 | J24: 244.27 | K24: =I24*J24 -> 0 | M24: 489.37 | N24: =L24*M24 -> 0 | V24: =+O24+P24+Q24+R24+S24+T24+U24-W24-X24 -> 0 | Y24: HECTOR
A25: CABO OBRA ELECTRICA | E25: hr | G25: 310.62 | H25: =F25*G25 -> 0 | J25: 335 | K25: =I25*J25 -> 0 | M25: 436.87 | N25: =L25*M25 -> 0 | V25: =+O25+P25+Q25+R25+S25+T25+U25-W25-X25 -> 0
A26: LINIERO | E26: hr | F26: 6 | G26: 209.25 | H26: =F26*G26 -> 1255.5 | J26: 221.7 | K26: =I26*J26 -> 0 | M26: 437.63 | N26: =L26*M26 -> 0 | V26: =+O26+P26+Q26+R26+S26+T26+U26-W26-X26 -> 0 | Y26: JOSE J
A27: ESPECIALISTA DE MANTTO ELECTRICO | E27: hr | G27: 237.68 | H27: =F27*G27 -> 0 | J27: 277.97 | K27: =I27*J27 -> 0 | M27: 538.84 | N27: =L27*M27 -> 0 | V27: =+O27+P27+Q27+R27+S27+T27+U27-W27-X27 -> 0
A28: TECNICO EN INSTRUMENTACION | E28: hr | G28: 368.59 | H28: =F28*G28 -> 0 | J28: 221.7 | K28: =I28*J28 -> 0 | M28: 538.84 | N28: =L28*M28 -> 0 | V28: =+O28+P28+Q28+R28+S28+T28+U28-W28-X28 -> 0
A29: OFICIAL ELECTRICO/ELECTROMECANICO | E29: hr | F29: 6 | G29: 190.22 | H29: =F29*G29 -> 1141.32 | J29: 165 | K29: =I29*J29 -> 0 | M29: 277.56 | N29: =L29*M29 -> 0 | V29: =+O29+P29+Q29+R29+S29+T29+U29-W29-X29 -> 0
A30: ASISTENTE DE DISEÑO | E30: hr | G30: 190.25 | H30: =F30*G30 -> 0 | J30: 221.7 | K30: =I30*J30 -> 0 | M30: 297.41 | N30: =L30*M30 -> 0 | V30: =+O30+P30+Q30+R30+S30+T30+U30-W30-X30 -> 0
A31: ELECTRICISTA -B | E31: hr | F31: 6 | G31: 119.54 | H31: =F31*G31 -> 717.24 | J31: 137.92 | K31: =I31*J31 -> 0 | M31: 0 | N31: =L31*M31 -> 0 | V31: =+O31+P31+Q31+R31+S31+T31+U31-W31-X31 -> 0 | Y31: GERMAN
A32: ELECTRICISTA -A | E32: hr | G32: 119.54 | H32: =F32*G32 -> 0 | J32: 137.92 | K32: =I32*J32 -> 0 | M32: 240.95 | N32: =L32*M32 -> 0 | V32: =+O32+P32+Q32+R32+S32+T32+U32-W32-X32 -> 0 | Y32: OSCAR-OSWALDO JIM
A33: AUXILIAR TECNICO | E33: hr | G33: 106.45 | H33: =F33*G33 -> 0 | J33: 137.92 | K33: =I33*J33 -> 0 | M33: 260.95 | N33: =L33*M33 -> 0 | V33: =+O33+P33+Q33+R33+S33+T33+U33-W33-X33 -> 0
A34: AYTE ELECTRICO - B | E34: hr | G34: 106.45 | H34: =F34*G34 -> 0 | J34: 122.4 | K34: =I34*J34 -> 0 | N34: =L34*M34 -> 0 | V34: =+O34+P34+Q34+R34+S34+T34+U34-W34-X34 -> 0
A35: AYTE DE ELECTR. -A | E35: hr | G35: 106.54 | H35: =F35*G35 -> 0 | J35: 122.4 | K35: =I35*J35 -> 0 | M35: 198.17 | N35: =L35*M35 -> 0 | V35: =+O35+P35+Q35+R35+S35+T35+U35-W35-X35 -> 0 | Y35: URIEL-GUILLERMO-ENRIQUE
A36: AYTE GENERAL | E36: hr | G36: 100.42 | H36: =F36*G36 -> 0 | J36: 122.4 | K36: =I36*J36 -> 0 | M36: 0 | N36: =L36*M36 -> 0 | V36: =+O36+P36+Q36+R36+S36+T36+U36-W36-X36 -> 0
A37: PROFESIONISTA | E37: hr | G37: 209.25 | H37: =F37*G37 -> 0 | J37: 406 | K37: =I37*J37 -> 0 | M37: 564.86 | N37: =L37*M37 -> 0 | V37: 0 | Y37: O.ZARCO-GABRIEL
A38: COORDINADOR DE OPERACIONES | E38: hr | G38: 0 | H38: =F38*G38 -> 0 | J38: 0 | K38: =I38*J38 -> 0 | M38: 0 | N38: =L38*M38 -> 0 | V38: =+O38+P38+Q38+R38+S38+T38+U38-W38-X38 -> 0
A39: INGENIERIA Y SOPORTE TEC. | E39: hr | G39: 339.75 | H39: =F39*G39 -> 0 | J39: 325.79 | K39: =I39*J39 -> 0 | M39: 488.68 | N39: =L39*M39 -> 0 | V39: =+O39+P39+Q39+R39+S39+T39+U39-W39-X39 -> 0
A40: INGENIERO DE SUBESTACIONES | E40: hr | G40: 339.75 | H40: =F40*G40 -> 0 | J40: 325.79 | K40: =I40*J40 -> 0 | M40: 488.68 | N40: =L40*M40 -> 0 | V40: =+O40+P40+Q40+R40+S40+T40+U40-W40-X40 -> 0
A41: INGENIERO DE PRUEBAS ELECTRICAS | E41: hr | G41: 339.75 | H41: =F41*G41 -> 0 | J41: 325.79 | K41: =I41*J41 -> 0 | M41: 488.68 | N41: =L41*M41 -> 0 | V41: =+O41+P41+Q41+R41+S41+T41+U41-W41-X41 -> 0
...

Sheet MAT (4)
A1: I M M E E S. A. D E C. V.
A2: A N A L I S I S D E P R E C I O U N I T A R I O
A3: COTIZACION:
A4: FECHA:
A5: PARTIDA 1
A6: REV-06-feb-2021
A7: MATERIALES.
A8: DESCRIPCION | E8: UNIDAD | F8: CANT. | G8: P.U. | H8: IMPORTE | J8: MATERIALES
A9: charola tipo escalera perfil Z para servicio pesado de 30" | E9: Pza | G9: 2540.01 | H9: =G9*F9 -> 0
A10: tapa para charola tipo escalera de 30". | E10: Pza | G10: 1001 | H10: =G10*F10 -> 0
A11: curva vertical exterior de 90° para charola tipo escalera de 30 | E11: Pza | G11: 450.5 | H11: =G11*F11 -> 0
A12: tapa para curva vertical exterior de 90° para charola tipo escalera para servicio pesado de 30" | E12: Pza | F12: 4 | G12: 136.52 | H12: =G12*F12 -> 546.08
A13: curva horizontal de 90° para charola tipo escalera para servicio pesado de 30" | E13: Pza | G13: 620.97 | H13: =G13*F13 -> 0
A14: base de unicanal solido galvanizado de 4x4 | E14: Pza | G14: 382.32 | H14: =G14*F14 -> 0
A15: tornilleria galvanizada | E15: Pza | G15: 200 | H15: =G15*F15 -> 0
A16: varilla roscada galvanizada de 3 metros de largo X 1/2" | E16: Pza | G16: 70 | H16: =G16*F16 -> 0
A17: conector de charola para servicio pesado de 30 | E17: Pza | G17: 467.05 | H17: =G17*F17 -> 0
A18: zapata ponchable para cable de cobre cañon largo calibre 500 KCM, con 2 ojillos de 1/2 | E18: Pza | G18: 495.41 | H18: =G18*F18 -> 0
A19: manga termocontractil para nivel de aislamiento de 600 V, en calibre 500 KCM. | E19: Pza | G19: 212.43 | H19: =G19*F19 -> 0
A20: tornillo tropicalizado de 1/2" con 2" de largo | E20: Pza | G20: 15 | H20: =G20*F20 -> 0
A21: tornillo tropicalizado de 1/2" con 4" de largo | E21: Pza | G21: 15 | H21: =G21*F21 -> 0
A22: sistema corta fuego con lana mineral y compuesto SF-ONE. | E22: Pza | G22: 698.25 | H22: =G22*F22 -> 0
A23: Materiales consumibles | E23: PZA | G23: 500 | H23: =G23*F23 -> 0
A24: cuellos de lona flexibles en gargantas primarias de generador electrico | E24: Pza | G24: 160.08 | H24: =G24*F24 -> 0
A25: cable de cobre THW calibre 12 AWG | E25: mt | G25: 12.63 | H25: =G25*F25 -> 0 | L25: NOTA: CONSIDERAR LA JORNADA DE 8.0 HORAS, AUNQUE EN IMMEE SE TRABAJE JORNADA LARGA CONVENIDA, Y DOMINGO DESCANSO
A26: tapones para unicanal de 4x4 y varilla roscada | E26: Pza | G26: 27.6 | H26: =G26*F26 -> 0
A27: tapones para esparrago | E27: Pza | G27: 70.34 | H27: =G27*F27 -> 0
A28: CONSUMIBLES | E28: 1 | F28: 1 | G28: 100 | H28: =G28*F28 -> 100
A29: Renta de una plataforma de elevacion | E29: Pza | G29: 48000 | H29: =G29*F29 -> 0 | I29: =H29*1.455 -> 0
G30: SUBT 1 | H30: =SUM(H9:H29) -> 646.08
A32: MANO DE OBRA SIN INDIRECTOS | O32: HORARIOS DE TRABAJO | V32: HORAS RESULTANTES | Y32: PERSONAL PEOPUESTO
A33: PERSONAL. | E33: UNIDAD | F33: CANT. | G33: HORA NORMAL | H33: IMPORTE | I33: CANT. | J33: Hr. Extra | K33: IMPORTE | L33: CANT. | M33: Dom, ó Fest.TRIPLE | N33: IMPORTE | O33: L | P33: M | Q33: MI | R33: J | S33: V | T33: S | U33: D | V33: N | W33: D | X33: T
A34: SUPERVISOR DE SEGURIDAD CERTIFICADO | E34: hr | G34: 390.39 | H34: =F34*G34 -> 0 | J34: 358.81 | K34: =I34*J34 -> 0 | M34: 538.27 | N34: =L34*M34 -> 0 | V34: =+O34+P34+Q34+R34+S34+T34+U34-W34-X34 -> 0
A35: SUPERVISOR DE SEGURIDAD | E35: hr | G35: 243.45 | H35: =F35*G35 -> 0 | J35: 211.59 | K35: =I35*J35 -> 0 | M35: 317.39 | N35: =L35*M35 -> 0 | V35: =+O35+P35+Q35+R35+S35+T35+U35-W35-X35 -> 0 | Y35: OSWALDO Z-GABRIEL
A36: SUPERVISOR ELECTRICO | E36: hr | G36: 390.39 | H36: =F36*G36 -> 0 | J36: 358.81 | K36: =I36*J36 -> 0 | M36: 538.22 | N36: =L36*M36 -> 0 | V36: =+O36+P36+Q36+R36+S36+T36+U36-W36-X36 -> 0 | Y36: ADRIAN
A37: TECNICO DE PRUEBAS ELECTRICAS | E37: hr | G37: 231.67 | H37: =F37*G37 -> 0 | J37: 197.63 | K37: =I37*J37 -> 0 | M37: 296.45 | N37: =L37*M37 -> 0 | V37: =+O37+P37+Q37+R37+S37+T37+U37-W37-X37 -> 0 | Y37: HECTOR
A38: CABO OBRA ELECTRICA | E38: hr | G38: 310.62 | H38: =F38*G38 -> 0 | J38: 291.24 | K38: =I38*J38 -> 0 | M38: 436.87 | N38: =L38*M38 -> 0 | V38: =+O38+P38+Q38+R38+S38+T38+U38-W38-X38 -> 0
A39: LINIERO | E39: hr | G39: 310.62 | H39: =F39*G39 -> 0 | J39: 291.24 | K39: =I39*J39 -> 0 | M39: 436.87 | N39: =L39*M39 -> 0 | V39: =+O39+P39+Q39+R39+S39+T39+U39-W39-X39 -> 0 | Y39: JOSE J
A40: ESPECIALISTA DE MANTTO ELECTRICO | E40: hr | H40: =F40*G40 -> 0 | J40: 0 | K40: =I40*J40 -> 0 | M40: 0 | N40: =L40*M40 -> 0 | V40: =+O40+P40+Q40+R40+S40+T40+U40-W40-X40 -> 0
A41: TECNICO EN INSTRUMENTACION | E41: hr | G41: 199.6 | H41: =F41*G41 -> 0 | J41: 159.6 | K41: =I41*J41 -> 0 | M41: 239.4 | N41: =L41*M41 -> 0 | V41: =+O41+P41+Q41+R41+S41+T41+U41-W41-X41 -> 0
...

Sheet M0  (4)
A1: I M M E E S. A. D E C. V.
A2: A N A L I S I S D E P R E C I O U N I T A R I O
A3: COTIZACION:
A4: FECHA:
A5: PARTIDA 1
A6: REV-06-feb-2021
A7: MATERIALES.
A8: DESCRIPCION | E8: UNIDAD | F8: CANT. | G8: P.U. | H8: IMPORTE | J8: MANO DE OBRA
A9: Consumible | E9: Pza | H9: =G9*F9 -> 0
E10: Pza | H10: =G10*F10 -> 0
E11: Pza | H11: =G11*F11 -> 0
E12: Pza | H12: =G12*F12 -> 0
E13: Pza | H13: =G13*F13 -> 0
E14: Pza | H14: =G14*F14 -> 0
E15: Pza | H15: =G15*F15 -> 0
E16: Pza | H16: =G16*F16 -> 0 | I16: =H16*1.455 -> 0
G17: SUBT 1 | H17: =SUM(H9:H16) -> 0
A19: MANO DE OBRA SIN INDIRECTOS | O19: HORARIOS DE TRABAJO | V19: HORAS RESULTANTES | Y19: PERSONAL PEOPUESTO
A20: PERSONAL. | E20: UNIDAD | F20: CANT. | G20: HORA NORMAL | H20: IMPORTE | I20: CANT. | J20: Hr. Extra | K20: IMPORTE | L20: CANT. | M20: Dom, ó Fest.TRIPLE | N20: IMPORTE | O20: L | P20: M | Q20: MI | R20: J | S20: V | T20: S | U20: D | V20: N | W20: D | X20: T
A21: SUPERVISOR DE SEGURIDAD CERTIFICADO | E21: hr | G21: 390.39 | H21: =F21*G21 -> 0 | J21: 358.81 | K21: =I21*J21 -> 0 | M21: 538.27 | N21: =L21*M21 -> 0 | V21: =+O21+P21+Q21+R21+S21+T21+U21-W21-X21 -> 0
A22: SUPERVISOR DE SEGURIDAD | E22: hr | G22: 317.98 | H22: =F22*G22 -> 0 | J22: 326.25 | K22: =I22*J22 -> 0 | M22: 489.37 | N22: =L22*M22 -> 0 | V22: =+O22+P22+Q22+R22+S22+T22+U22-W22-X22 -> 0 | Y22: OSWALDO Z-GABRIEL
A23: SUPERVISOR ELECTRICO | E23: hr | F23: 1 | G23: 237.68 | H23: =F23*G23 -> 237.68 | I23: 0 | J23: 358.81 | K23: =I23*J23 -> 0 | M23: 538.22 | N23: =L23*M23 -> 0 | V23: =+O23+P23+Q23+R23+S23+T23+U23-W23-X23 -> 0 | Y23: ADRIAN
A24: TECNICO DE PRUEBAS ELECTRICAS | E24: hr | G24: 317.98 | H24: =F24*G24 -> 0 | J24: 244.27 | K24: =I24*J24 -> 0 | M24: 489.37 | N24: =L24*M24 -> 0 | V24: =+O24+P24+Q24+R24+S24+T24+U24-W24-X24 -> 0 | Y24: HECTOR
A25: CABO OBRA ELECTRICA | E25: hr | G25: 310.62 | H25: =F25*G25 -> 0 | J25: 335 | K25: =I25*J25 -> 0 | M25: 436.87 | N25: =L25*M25 -> 0 | V25: =+O25+P25+Q25+R25+S25+T25+U25-W25-X25 -> 0
A26: LINIERO | E26: hr | F26: 2 | G26: 209.25 | H26: =F26*G26 -> 418.5 | I26: 0 | J26: 221.7 | K26: =I26*J26 -> 0 | M26: 437.63 | N26: =L26*M26 -> 0 | V26: =+O26+P26+Q26+R26+S26+T26+U26-W26-X26 -> 0 | Y26: JOSE J
A27: ESPECIALISTA DE MANTTO ELECTRICO | E27: hr | G27: 237.68 | H27: =F27*G27 -> 0 | J27: 277.97 | K27: =I27*J27 -> 0 | M27: 538.84 | N27: =L27*M27 -> 0 | V27: =+O27+P27+Q27+R27+S27+T27+U27-W27-X27 -> 0
A28: TECNICO EN INSTRUMENTACION | E28: hr | G28: 368.59 | H28: =F28*G28 -> 0 | J28: 221.7 | K28: =I28*J28 -> 0 | M28: 538.84 | N28: =L28*M28 -> 0 | V28: =+O28+P28+Q28+R28+S28+T28+U28-W28-X28 -> 0
A29: OFICIAL ELECTRICO/ELECTROMECANICO | E29: hr | F29: 2 | G29: 190.22 | H29: =F29*G29 -> 380.44 | I29: 0 | J29: 165 | K29: =I29*J29 -> 0 | M29: 277.56 | N29: =L29*M29 -> 0 | V29: =+O29+P29+Q29+R29+S29+T29+U29-W29-X29 -> 0
A30: ASISTENTE DE DISEÑO | E30: hr | G30: 190.25 | H30: =F30*G30 -> 0 | J30: 221.7 | K30: =I30*J30 -> 0 | M30: 297.41 | N30: =L30*M30 -> 0 | V30: =+O30+P30+Q30+R30+S30+T30+U30-W30-X30 -> 0
A31: ELECTRICISTA -B | E31: hr | F31: 1 | G31: 119.54 | H31: =F31*G31 -> 119.54 | I31: 0 | J31: 137.92 | K31: =I31*J31 -> 0 | M31: 0 | N31: =L31*M31 -> 0 | V31: =+O31+P31+Q31+R31+S31+T31+U31-W31-X31 -> 0 | Y31: GERMAN
A32: ELECTRICISTA -A | E32: hr | G32: 119.54 | H32: =F32*G32 -> 0 | J32: 137.92 | K32: =I32*J32 -> 0 | M32: 240.95 | N32: =L32*M32 -> 0 | V32: =+O32+P32+Q32+R32+S32+T32+U32-W32-X32 -> 0 | Y32: OSCAR-OSWALDO JIM
A33: AUXILIAR TECNICO | E33: hr | G33: 106.45 | H33: =F33*G33 -> 0 | J33: 137.92 | K33: =I33*J33 -> 0 | M33: 260.95 | N33: =L33*M33 -> 0 | V33: =+O33+P33+Q33+R33+S33+T33+U33-W33-X33 -> 0
A34: AYTE ELECTRICO - B | E34: hr | G34: 106.45 | H34: =F34*G34 -> 0 | J34: 122.4 | K34: =I34*J34 -> 0 | N34: =L34*M34 -> 0 | V34: =+O34+P34+Q34+R34+S34+T34+U34-W34-X34 -> 0
A35: AYTE DE ELECTR. -A | E35: hr | G35: 106.54 | H35: =F35*G35 -> 0 | J35: 122.4 | K35: =I35*J35 -> 0 | M35: 198.17 | N35: =L35*M35 -> 0 | V35: =+O35+P35+Q35+R35+S35+T35+U35-W35-X35 -> 0 | Y35: URIEL-GUILLERMO-ENRIQUE
A36: AYTE GENERAL | E36: hr | G36: 100.42 | H36: =F36*G36 -> 0 | J36: 122.4 | K36: =I36*J36 -> 0 | M36: 0 | N36: =L36*M36 -> 0 | V36: =+O36+P36+Q36+R36+S36+T36+U36-W36-X36 -> 0
A37: PROFESIONISTA | E37: hr | G37: 209.25 | H37: =F37*G37 -> 0 | J37: 406 | K37: =I37*J37 -> 0 | M37: 564.86 | N37: =L37*M37 -> 0 | V37: 0 | Y37: O.ZARCO-GABRIEL
A38: COORDINADOR DE OPERACIONES | E38: hr | G38: 0 | H38: =F38*G38 -> 0 | J38: 0 | K38: =I38*J38 -> 0 | M38: 0 | N38: =L38*M38 -> 0 | V38: =+O38+P38+Q38+R38+S38+T38+U38-W38-X38 -> 0
A39: INGENIERIA Y SOPORTE TEC. | E39: hr | G39: 339.75 | H39: =F39*G39 -> 0 | J39: 325.79 | K39: =I39*J39 -> 0 | M39: 488.68 | N39: =L39*M39 -> 0 | V39: =+O39+P39+Q39+R39+S39+T39+U39-W39-X39 -> 0
A40: INGENIERO DE SUBESTACIONES | E40: hr | G40: 339.75 | H40: =F40*G40 -> 0 | J40: 325.79 | K40: =I40*J40 -> 0 | M40: 488.68 | N40: =L40*M40 -> 0 | V40: =+O40+P40+Q40+R40+S40+T40+U40-W40-X40 -> 0
A41: INGENIERO DE PRUEBAS ELECTRICAS | E41: hr | G41: 339.75 | H41: =F41*G41 -> 0 | J41: 325.79 | K41: =I41*J41 -> 0 | M41: 488.68 | N41: =L41*M41 -> 0 | V41: =+O41+P41+Q41+R41+S41+T41+U41-W41-X41 -> 0
...

Sheet MAT (5)
A1: I M M E E S. A. D E C. V.
A2: A N A L I S I S D E P R E C I O U N I T A R I O
A3: COTIZACION:
A4: FECHA:
A5: PARTIDA 1
A6: REV-06-feb-2021
A7: MATERIALES.
A8: DESCRIPCION | E8: UNIDAD | F8: CANT. | G8: P.U. | H8: IMPORTE | J8: MATERIALES
A9: charola tipo escalera perfil Z para servicio pesado de 30" | E9: Pza | G9: 2540.01 | H9: =G9*F9 -> 0
A10: tapa para charola tipo escalera de 30". | E10: Pza | G10: 1001 | H10: =G10*F10 -> 0
A11: curva vertical exterior de 90° para charola tipo escalera de 30 | E11: Pza | G11: 450.5 | H11: =G11*F11 -> 0
A12: tapa para curva vertical exterior de 90° para charola tipo escalera para servicio pesado de 30" | E12: Pza | G12: 136.52 | H12: =G12*F12 -> 0
A13: curva horizontal de 90° para charola tipo escalera para servicio pesado de 30" | E13: Pza | G13: 620.97 | H13: =G13*F13 -> 0
A14: base de unicanal solido galvanizado de 4x4 | E14: Pza | F14: 3 | G14: 382.32 | H14: =G14*F14 -> 1146.96
A15: tornilleria galvanizada | E15: Pza | F15: 3 | G15: 200 | H15: =G15*F15 -> 600
A16: varilla roscada galvanizada de 3 metros de largo X 1/2" | E16: Pza | F16: 6 | G16: 70 | H16: =G16*F16 -> 420
A17: conector de charola para servicio pesado de 30 | E17: Pza | F17: 6 | G17: 467.05 | H17: =G17*F17 -> 2802.3
A18: zapata ponchable para cable de cobre cañon largo calibre 500 KCM, con 2 ojillos de 1/2 | E18: Pza | G18: 495.41 | H18: =G18*F18 -> 0
A19: manga termocontractil para nivel de aislamiento de 600 V, en calibre 500 KCM. | E19: Pza | G19: 212.43 | H19: =G19*F19 -> 0
A20: tornillo tropicalizado de 1/2" con 2" de largo | E20: Pza | G20: 15 | H20: =G20*F20 -> 0
A21: tornillo tropicalizado de 1/2" con 4" de largo | E21: Pza | G21: 15 | H21: =G21*F21 -> 0
A22: sistema corta fuego con lana mineral y compuesto SF-ONE. | E22: Pza | G22: 698.25 | H22: =G22*F22 -> 0
A23: Materiales consumibles | E23: PZA | G23: 500 | H23: =G23*F23 -> 0
A24: cuellos de lona flexibles en gargantas primarias de generador electrico | E24: Pza | G24: 160.08 | H24: =G24*F24 -> 0
A25: cable de cobre THW calibre 12 AWG | E25: mt | G25: 12.63 | H25: =G25*F25 -> 0 | L25: NOTA: CONSIDERAR LA JORNADA DE 8.0 HORAS, AUNQUE EN IMMEE SE TRABAJE JORNADA LARGA CONVENIDA, Y DOMINGO DESCANSO
A26: tapones para unicanal de 4x4 y varilla roscada | E26: Pza | G26: 27.6 | H26: =G26*F26 -> 0
A27: tapones para esparrago | E27: Pza | G27: 70.34 | H27: =G27*F27 -> 0
A28: consumibles | E28: 1 | G28: 100 | H28: =G28*F28 -> 0
A29: Renta de una plataforma de elevacion | E29: Pza | G29: 25000 | H29: =G29*F29 -> 0 | I29: =H29*1.455 -> 0
G30: SUBT 1 | H30: =SUM(H9:H29) -> 4969.26
A32: MANO DE OBRA SIN INDIRECTOS | O32: HORARIOS DE TRABAJO | V32: HORAS RESULTANTES | Y32: PERSONAL PEOPUESTO
A33: PERSONAL. | E33: UNIDAD | F33: CANT. | G33: HORA NORMAL | H33: IMPORTE | I33: CANT. | J33: Hr. Extra | K33: IMPORTE | L33: CANT. | M33: Dom, ó Fest.TRIPLE | N33: IMPORTE | O33: L | P33: M | Q33: MI | R33: J | S33: V | T33: S | U33: D | V33: N | W33: D | X33: T
A34: SUPERVISOR DE SEGURIDAD CERTIFICADO | E34: hr | G34: 390.39 | H34: =F34*G34 -> 0 | J34: 358.81 | K34: =I34*J34 -> 0 | M34: 538.27 | N34: =L34*M34 -> 0 | V34: =+O34+P34+Q34+R34+S34+T34+U34-W34-X34 -> 0
A35: SUPERVISOR DE SEGURIDAD | E35: hr | G35: 243.45 | H35: =F35*G35 -> 0 | J35: 211.59 | K35: =I35*J35 -> 0 | M35: 317.39 | N35: =L35*M35 -> 0 | V35: =+O35+P35+Q35+R35+S35+T35+U35-W35-X35 -> 0 | Y35: OSWALDO Z-GABRIEL
A36: SUPERVISOR ELECTRICO | E36: hr | G36: 390.39 | H36: =F36*G36 -> 0 | J36: 358.81 | K36: =I36*J36 -> 0 | M36: 538.22 | N36: =L36*M36 -> 0 | V36: =+O36+P36+Q36+R36+S36+T36+U36-W36-X36 -> 0 | Y36: ADRIAN
A37: TECNICO DE PRUEBAS ELECTRICAS | E37: hr | G37: 231.67 | H37: =F37*G37 -> 0 | J37: 197.63 | K37: =I37*J37 -> 0 | M37: 296.45 | N37: =L37*M37 -> 0 | V37: =+O37+P37+Q37+R37+S37+T37+U37-W37-X37 -> 0 | Y37: HECTOR
A38: CABO OBRA ELECTRICA | E38: hr | G38: 310.62 | H38: =F38*G38 -> 0 | J38: 291.24 | K38: =I38*J38 -> 0 | M38: 436.87 | N38: =L38*M38 -> 0 | V38: =+O38+P38+Q38+R38+S38+T38+U38-W38-X38 -> 0
A39: LINIERO | E39: hr | G39: 310.62 | H39: =F39*G39 -> 0 | J39: 291.24 | K39: =I39*J39 -> 0 | M39: 436.87 | N39: =L39*M39 -> 0 | V39: =+O39+P39+Q39+R39+S39+T39+U39-W39-X39 -> 0 | Y39: JOSE J
A40: ESPECIALISTA DE MANTTO ELECTRICO | E40: hr | H40: =F40*G40 -> 0 | J40: 0 | K40: =I40*J40 -> 0 | M40: 0 | N40: =L40*M40 -> 0 | V40: =+O40+P40+Q40+R40+S40+T40+U40-W40-X40 -> 0
